Workbook

Sheet план сентябрь
A1: План реализации щебня в сентябре 2021 г.
A4: Покупатель | B4: Объем, тн | C4: Цена FCA, руб/тн без НДС | D4: Сумма, руб без НДС | E4: Стоимость доставки(ЖД, авто), руб/тн безНДС | F4: Цена с доставкой, руб/тн без НДС
A5: Щебень фр. 5-20 мм
A6: М-неруд | B6: 10000 | C6: 425 | D6: =B6*C6 -> 4250000 | F6: =C6+E6 -> 425 | G6: =B6*E6 -> 0
A7: Прочие | B7: 50000 | C7: 518 | D7: =B7*C7 -> 25900000 | F7: =C7+E7 -> 518 | G7: =B7*E7 -> 0
A8: Итого Щебень фр. 5-20 мм | B8: =SUM(B6:B7) -> 60000 | C8: =D8/B8 -> 502.5 | D8: =SUM(D6:D7) -> 30150000 | G8: =B8*E8 -> 0
A9: Щебень фр. 20-40 мм | G9: =B9*E9 -> 0
A10: Брянскавтодор | B10: 3500 | C10: 62 | D10: =B10*C10 -> 217000 | E10: 678 | F10: =C10+E10 -> 740 | G10: =B10*E10 -> 2373000
A11: М-неруд | B11: 10000 | C11: 425 | D11: =B11*C11 -> 4250000 | F11: =C11+E11 -> 425 | G11: =B11*E11 -> 0
A12: Прочие | B12: 36500 | C12: 518 | D12: =B12*C12 -> 18907000 | F12: =C12+E12 -> 518 | G12: =B12*E12 -> 0
A13: Итого Щебень фр. 20-40 мм | B13: =SUM(B10:B12) -> 50000 | C13: =D13/B13 -> 467.48 | D13: =SUM(D10:D12) -> 23374000 | G13: =B13*E13 -> 0
A14: Щебень металлургический фр. 20-50 мм | G14: =B14*E14 -> 0
A15: ТД Оскол | B15: 10000 | C15: 670 | D15: =B15*C15 -> 6700000 | E15: 1533 | F15: =C15+E15 -> 2203 | G15: =B15*E15 -> 15330000
A16: Итого Щебень металлургический фр.20-50 мм | B16: =SUM(B15:B15) -> 10000 | C16: =D16/B16 -> 670 | D16: =SUM(D15:D15) -> 6700000 | G16: =B16*E16 -> 0
A17: Щебень дорожный фр. 40-70 мм | G17: =B17*E17 -> 0
A18: Брянскавтодор | B18: 3500 | C18: 62 | D18: =B18*C18 -> 217000 | E18: 678 | F18: =C18+E18 -> 740 | G18: =B18*E18 -> 2373000
A19: Итого Щебень дорожный фр.40-70 мм | B19: =SUM(B18:B18) -> 3500 | C19: =D19/B19 -> 62 | D19: =SUM(D18:D18) -> 217000 | G19: =B19*E19 -> 0
A20: Щебень металлургический фр. 40-70 мм | G20: =B20*E20 -> 0
A21: БМЗ | B21: 42000 | C21: 157 | D21: =B21*C21 -> 6594000 | E21: 833 | F21: =C21+E21 -> 990 | G21: =B21*E21 -> 34986000
A22: Бежицкая сталь | B22: 210 | C22: 349 | D22: =B22*C22 -> 73290 | E22: 585 | F22: =C22+E22 -> 934 | G22: =B22*E22 -> 122850
A23: Слуцкий СК | B23: 7000 | C23: 904 | D23: =B23*C23 -> 6328000 | E23: 986 | F23: =C23+E23 -> 1890 | G23: =B23*E23 -> 6902000
A24: Укрхимфлюсы | B24: 7000 | C24: 670 | D24: =C24*B24 -> 4690000 | E24: 1533 | F24: =C24+E24 -> 2203 | G24: =B24*E24 -> 10731000
A25: Итого Щебень металлургический фр.40-70 мм | B25: =SUM(B21:B24) -> 56210 | C25: =D25/B25 -> 314.62889 | D25: =SUM(D21:D24) -> 17685290 | G25: =B25*E25 -> 0
A26: Итого Щебень фр.40-70 мм | B26: =B25+B19 -> 59710 | C26: =D26/B26 -> 299.82063 | D26: =D25+D19 -> 17902290 | G26: =B26*E26 -> 0
A27: Щебень металлургический фр. 70-90 мм | G27: =B27*E27 -> 0
A28: Эртильский сахарник | B28: 4500 | C28: 450 | D28: =B28*C28 -> 2025000 | E28: 753 | F28: =C28+E28 -> 1203 | G28: =B28*E28 -> 3388500
A29: Елань-Коленовский СЗ | B29: 4200 | C29: 466 | D29: =C29*B29 -> 1957200 | E29: 984 | F29: =C29+E29 -> 1450 | G29: =B29*E29 -> 4132800
A30: Итого Щебень металлургический фр. 70-90 мм | B30: =SUM(B28:B29) -> 8700 | C30: =D30/B30 -> 457.72414 | D30: =SUM(D28:D29) -> 3982200 | G30: =B30*E30 -> 0
A31: Щебень металлургический фр. 70-120 мм | G31: =B31*E31 -> 0
A32: Дмитротарановский СЗ | B32: 3700 | C32: 520 | D32: =C32*B32 -> 1924000 | E32: 767.5 | F32: =C32+E32 -> 1287.5 | G32: =B32*E32 -> 2839750
A33: Жабиновский СК | B33: 7000 | C33: 1003 | D33: =C33*B33 -> 7021000 | E33: 1037 | F33: =C33+E33 -> 2040 | G33: =B33*E33 -> 7259000
A34: Земетчинский СЗ | B34: 2100 | C34: 575 | D34: =C34*B34 -> 1207500 | E34: 840.84 | F34: =C34+E34 -> 1415.84 | G34: =B34*E34 -> 1765764
A35: Кристалл | B35: 4200 | C35: 505 | D35: =C35*B35 -> 2121000 | E35: 1070 | F35: =C35+E35 -> 1575 | G35: =B35*E35 -> 4494000
A36: КСП-Любимовский | B36: 1200 | C36: 529 | D36: =C36*B36 -> 634800 | E36: 697 | F36: =C36+E36 -> 1226 | G36: =B36*E36 -> 836400 | L36: =B37+B39 -> 11000
A37: Новомосковский Хлор | B37: 7000 | C37: 383 | D37: =C37*B37 -> 2681000 | E37: 167 | F37: =C37+E37 -> 550 | G37: =B37*E37 -> 1169000
A38: Ольховатский СЗ | B38: 7200 | C38: 560 | D38: =C38*B38 -> 4032000 | E38: 1096 | F38: =C38+E38 -> 1656 | G38: =B38*E38 -> 7891200
A39: Отрадинский СЗ | B39: 4000 | C39: 145 | D39: =C39*B39 -> 580000 | E39: 458 | F39: =C39+E39 -> 603 | G39: =B39*E39 -> 1832000
A40: Промсахар(вагоны Покупателя) | B40: 3500 | C40: 400 | D40: =C40*B40 -> 1400000 | F40: =C40+E40 -> 400 | G40: =B40*E40 -> 0
A41: Скидельский СК | B41: 7000 | C41: 1009 | D41: =C41*B41 -> 7063000 | E41: 1031 | F41: =C41+E41 -> 2040 | G41: =B41*E41 -> 7217000
A42: Фельс Известь г.Калуга ООО(самовывоз) | B42: 12000 | C42: 439 | D42: =C42*B42 -> 5268000 | F42: =C42+E42 -> 439 | G42: =B42*E42 -> 0
...

Sheet краткий сентябрь
B2: УТВЕРЖДАЮ
B5: Исполнительный директор
B6: Н.Н. Слащева
B7: Дата . .2021 г.
A12: План реализации Щебня в сентябре 2021 г.
A14: наименование | B14: Объем, тн | C14: Сумма | D14: Цена FCA, руб/тн с НДС | E14: Сумма, руб с НДС | F14: Стоимость доставки, руб/тн
A15: Щебень фр. 5-20 мм | B15: ='план сентябрь'!B8 -> 60000 | C15: =SUM(#REF!) -> #REF! | D15: =E15/B15 -> #REF! | E15: =SUM(#REF!) -> #REF!
A16: Щебень фр. 20-40 мм | B16: ='план сентябрь'!B13 -> 50000 | C16: =SUM(#REF!) -> #REF! | D16: =E16/B16 -> #REF! | E16: =SUM(#REF!) -> #REF!
A17: Щебень металлургический фр. 20-50 мм | B17: ='план сентябрь'!B16 -> 10000
A18: Щебень металлургический фр. 40-70 мм | B18: ='план сентябрь'!B25 -> 56210 | C18: =SUM(#REF!) -> #REF! | D18: =E18/B18 -> #REF! | E18: =SUM(#REF!) -> #REF!
A19: Щебень дорожный фр. 40-70 мм | B19: ='план сентябрь'!B19 -> 3500 | C19: =SUM(#REF!) -> #REF! | D19: =E19/B19 -> #REF! | E19: =SUM(#REF!) -> #REF!
A20: Щебень металлургический фр. 70-90 мм | B20: ='план сентябрь'!B30 -> 8700
A21: Щебень металлургический фр. 70-120 мм | B21: ='план сентябрь'!B43 -> 58900 | C21: =SUM(#REF!) -> #REF! | D21: 462 | E21: =SUM(#REF!) -> #REF!
A22: Всего щебня | B22: =B15+B16+B17+B18+B19+B21+B20 -> 247310 | C22: =#REF!+#REF!+#REF! -> #REF! | D22: =E22/B22 -> #REF! | E22: =#REF!+E19+E16+E15+#REF! -> #REF!
A27: Коммерческий директор | B27: А.В. Исаев | F27: А.В. Исаев
A29: Зам. коммерческого директора | B29: Б.Л. Григорян | F29: Б.Л. Григорян
A31: Вед. специалист коммерческой службы | B31: Т.А. Зубко | E31: Т.А. Зубко
A33: Вед. специалист коммерческой службы | B33: В.И. Быков
