Workbook

Sheet план май
A1: План реализации щебня в мае 2021 г.
A4: Покупатель | B4: План реализации на май 2021 г.
B5: Объем, тн | C5: Цена FCA, руб/тн без НДС | D5: Сумма, руб без НДС | E5: Стоимость доставки(ЖД, авто), руб/тн безНДС | F5: Цена с доставкой, руб/тн без НДС
A6: Щебень фр. 5-20 мм
A7: М-неруд | B7: 6000 | C7: 425 | D7: =B7*C7 -> 2550000 | F7: =C7+E7 -> 425 | G7: =B7*E7 -> 0
A8: Прочие | B8: 84000 | C8: 483 | D8: =B8*C8 -> 40572000 | F8: =C8+E8 -> 483 | G8: =B8*E8 -> 0
A9: Итого Щебень фр. 5-20 мм | B9: =SUM(B7:B8) -> 90000 | C9: =D9/B9 -> 479.13333 | D9: =SUM(D7:D8) -> 43122000 | G9: =B9*E9 -> 0
A10: Щебень фр. 20-40 мм | G10: =B10*E10 -> 0
A11: Брянскавтодор | B11: 14000 | C11: 383 | D11: =B11*C11 -> 5362000 | E11: 336 | F11: =C11+E11 -> 719 | G11: =B11*E11 -> 4704000
A12: ДорЭлит | B12: 1400 | C12: 467 | D12: =B12*C12 -> 653800 | E12: 360 | F12: =C12+E12 -> 827 | G12: =B12*E12 -> 504000
A13: М-неруд | B13: 15000 | C13: 425 | D13: =B13*C13 -> 6375000 | F13: =C13+E13 -> 425 | G13: =B13*E13 -> 0
A14: Прочие | B14: 36000 | C14: 483 | D14: =B14*C14 -> 17388000 | F14: =C14+E14 -> 483 | G14: =B14*E14 -> 0
A15: Итого Щебень фр. 20-40 мм | B15: =SUM(B11:B14) -> 66400 | C15: =D15/B15 -> 448.4759 | D15: =SUM(D11:D14) -> 29778800 | G15: =B15*E15 -> 0
A16: Щебень фр. 20-50 мм | G16: =B16*E16 -> 0
A17: Оскол ТД | B17: 15000 | C17: 527 | D17: =B17*C17 -> 7905000 | E17: 663 | F17: =C17+E17 -> 1190 | G17: =B17*E17 -> 9945000
A18: Итого Щебень фр. 20-50 мм | B18: =SUM(B17:B17) -> 15000 | C18: =D18/B18 -> 527 | D18: =SUM(D17:D17) -> 7905000 | G18: =B18*E18 -> 0
A19: Щебень дорожный фр. 40-70 мм | G19: =B19*E19 -> 0
A20: Брянскавтодор | B20: 7000 | C20: 383 | D20: =B20*C20 -> 2681000 | E20: 336 | F20: =C20+E20 -> 719 | G20: =B20*E20 -> 2352000
A21: ДорЭлит | B21: 9000 | C21: 467 | D21: =B21*C21 -> 4203000 | E21: 360 | F21: =C21+E21 -> 827 | G21: =B21*E21 -> 3240000
A22: М-неруд | B22: 10000 | C22: 425 | D22: =B22*C22 -> 4250000 | F22: =C22+E22 -> 425
A23: Прочие | B23: 15000 | C23: 483 | D23: =B23*C23 -> 7245000 | F23: =C23+E23 -> 483 | G23: =B23*E23 -> 0
A24: Итого Щебень дорожный фр.40-70 мм | B24: =SUM(B20:B23) -> 41000 | C24: =D24/B24 -> 448.26829 | D24: =SUM(D20:D23) -> 18379000 | G24: =B24*E24 -> 0
A25: Щебень металлургический фр. 40-70 мм | G25: =B25*E25 -> 0
A26: Бежицкая сталь | B26: 207 | C26: 319 | D26: =B26*C26 -> 66033 | E26: 356 | F26: =C26+E26 -> 675 | G26: =B26*E26 -> 73692
A27: БМЗ | B27: 7500 | C27: 422 | D27: =B27*C27 -> 3165000 | E27: 568 | F27: =C27+E27 -> 990 | G27: =B27*E27 -> 4260000
A28: КМЗ | B28: 9000 | C28: 308 | D28: =B28*C28 -> 2772000 | F28: =C28+E28 -> 308 | G28: =B28*E28 -> 0
A29: Укрхимтрейдинг | B29: 10000 | C29: 467 | D29: =C29*B29 -> 4670000 | E29: 722 | F29: =C29+E29 -> 1189 | G29: =B29*E29 -> 7220000
A30: Укрхимфлюсы | B30: 10000 | C30: 467 | D30: =C30*B30 -> 4670000 | E30: 722 | F30: =C30+E30 -> 1189 | G30: =B30*E30 -> 7220000
A31: Итого Щебень металлургический фр.40-70 мм | B31: =SUM(B26:B30) -> 36707 | C31: =D31/B31 -> 417.98657 | D31: =SUM(D26:D30) -> 15343033 | G31: =B31*E31 -> 0
A32: Итого Щебень фр.40-70 мм | B32: =B31+B24 -> 77707 | C32: =D32/B32 -> 433.9639 | D32: =D31+D24 -> 33722033 | G32: =B32*E32 -> 0
A33: Щебень металлургический фр. 70-90 мм | G33: =B33*E33 -> 0
A34: Елань-Коленовский СЗ | B34: 3500 | C34: 338 | D34: =B34*C34 -> 1183000 | E34: 584 | F34: =C34+E34 -> 922 | G34: =B34*E34 -> 2044000
A35: Эртильский сахарник | B35: 4200 | C35: 256 | D35: =B35*C35 -> 1075200 | E35: 465 | F35: =C35+E35 -> 721 | G35: =B35*E35 -> 1953000
A36: Итого Щебень металлургический фр. 70-90 мм | B36: =SUM(B34:B35) -> 7700 | C36: =D36/B36 -> 293.27273 | D36: =SUM(D34:D35) -> 2258200 | G36: =B36*E36 -> 0
A37: БМЗ | B37: 7500 | C37: 422 | D37: =B37*C37 -> 3165000 | E37: 568 | F37: =C37+E37 -> 990 | G37: =B37*E37 -> 4260000
A38: Дмитротарановский СЗ | B38: 3300 | C38: 355 | D38: =C38*B38 -> 1171500 | E38: 494 | F38: =C38+E38 -> 849 | G38: =B38*E38 -> 1630200
A39: Елань-Коленовский СЗ | B39: 3500 | C39: 338 | D39: =C39*B39 -> 1183000 | E39: 584 | F39: =C39+E39 -> 922 | G39: =B39*E39 -> 2044000
A40: Земетчинский СЗ | B40: 4200 | C40: 399 | D40: =C40*B40 -> 1675800 | E40: 525 | F40: =C40+E40 -> 924 | G40: =B40*E40 -> 2205000
A41: Кристалл | B41: 3700 | C41: 334 | D41: =C41*B41 -> 1235800 | E41: 603 | F41: =C41+E41 -> 937 | G41: =B41*E41 -> 2231100
A42: КСП-Золотухинский | B42: 6200 | C42: 334 | D42: =C42*B42 -> 2070800 | E42: 386 | F42: =C42+E42 -> 720 | G42: =B42*E42 -> 2393200
...

Sheet краткий май
B2: УТВЕРЖДАЮ
B5: Исполнительный директор
B6: Н.Н. Слащева
B7: Дата . .2021 г.
A12: План реализации Щебня в мае 2021 г.
A14: наименование | B14: Объем, тн | C14: Сумма | D14: Цена FCA, руб/тн с НДС | E14: Сумма, руб с НДС | F14: Стоимость доставки, руб/тн
A15: Щебень фр. 5-20 мм | B15: ='план май'!B9 -> 90000 | C15: =SUM(#REF!) -> #REF! | D15: =E15/B15 -> #REF! | E15: =SUM(#REF!) -> #REF!
A16: Щебень фр. 20-40 мм | B16: ='план май'!B15 -> 66400 | C16: =SUM(#REF!) -> #REF! | D16: =E16/B16 -> #REF! | E16: =SUM(#REF!) -> #REF!
A17: Щебень металлургический фр. 20-50 мм | B17: ='план май'!B18 -> 15000
A18: Щебень металлургический фр. 40-70 мм | B18: ='план май'!B31 -> 36707 | C18: =SUM(#REF!) -> #REF! | D18: =E18/B18 -> #REF! | E18: =SUM(#REF!) -> #REF!
A19: Щебень дорожный фр. 40-70 мм | B19: ='план май'!B24 -> 41000 | C19: =SUM(#REF!) -> #REF! | D19: =E19/B19 -> #REF! | E19: =SUM(#REF!) -> #REF!
A20: Щебень металлургический фр. 70-90 мм | B20: ='план май'!B36 -> 7700
A21: Щебень металлургический фр. 70-120 мм | B21: ='план май'!B48 -> 63800 | C21: =SUM(#REF!) -> #REF! | D21: 462 | E21: =SUM(#REF!) -> #REF!
A22: Всего щебня | B22: =B15+B16+B17+B18+B19+B21+B20 -> 320607 | C22: =#REF!+#REF!+#REF! -> #REF! | D22: =E22/B22 -> #REF! | E22: =#REF!+E19+E16+E15+#REF! -> #REF!
A27: Коммерческий директор | B27: А.В. Исаев | F27: А.В. Исаев
A29: Зам. коммерческого директора | B29: Б.Л. Григорян | F29: Б.Л. Григорян
A31: Вед. специалист коммерческой службы | B31: Т.А. Зубко | E31: Т.А. Зубко
A33: Вед. специалист коммерческой службы | B33: В.И. Быков
